[2025-10-30T01:56:33.294+0000] {taskinstance.py:1956} INFO - Dependencies all met for dep_context=non-requeueable deps ti=<TaskInstance: dbt_local_pipeline.dbt_run manual__2025-10-30T01:56:24.022091+00:00 [queued]>
[2025-10-30T01:56:33.380+0000] {taskinstance.py:1956} INFO - Dependencies all met for dep_context=requeueable deps ti=<TaskInstance: dbt_local_pipeline.dbt_run manual__2025-10-30T01:56:24.022091+00:00 [queued]>
[2025-10-30T01:56:33.382+0000] {taskinstance.py:2170} INFO - Starting attempt 1 of 2
[2025-10-30T01:56:33.501+0000] {taskinstance.py:2191} INFO - Executing <Task(BashOperator): dbt_run> on 2025-10-30 01:56:24.022091+00:00
[2025-10-30T01:56:33.563+0000] {standard_task_runner.py:60} INFO - Started process 537 to run task
[2025-10-30T01:56:33.571+0000] {standard_task_runner.py:87} INFO - Running: ['***', 'tasks', 'run', 'dbt_local_pipeline', 'dbt_run', 'manual__2025-10-30T01:56:24.022091+00:00', '--job-id', '279', '--raw', '--subdir', 'DAGS_FOLDER/dbt_local_dag.py', '--cfg-path', '/tmp/tmpw1_c9r_n']
[2025-10-30T01:56:33.573+0000] {standard_task_runner.py:88} INFO - Job 279: Subtask dbt_run
[2025-10-30T01:56:34.053+0000] {task_command.py:423} INFO - Running <TaskInstance: dbt_local_pipeline.dbt_run manual__2025-10-30T01:56:24.022091+00:00 [running]> on host e51a0d90683d
[2025-10-30T01:56:34.581+0000] {taskinstance.py:2480} INFO - Exporting env vars: AIRFLOW_CTX_DAG_OWNER='winardi' AIRFLOW_CTX_DAG_ID='dbt_local_pipeline' AIRFLOW_CTX_TASK_ID='dbt_run' AIRFLOW_CTX_EXECUTION_DATE='2025-10-30T01:56:24.022091+00:00' AIRFLOW_CTX_TRY_NUMBER='1' AIRFLOW_CTX_DAG_RUN_ID='manual__2025-10-30T01:56:24.022091+00:00'
[2025-10-30T01:56:34.595+0000] {subprocess.py:63} INFO - Tmp dir root location: /tmp
[2025-10-30T01:56:34.611+0000] {subprocess.py:75} INFO - Running command: ['/usr/bin/bash', '-c', '\n            cd /opt/***/include/dbt/dbt_project &&             dbt run --profiles-dir /home/***/.dbt --target dev\n        ']
[2025-10-30T01:56:34.753+0000] {subprocess.py:86} INFO - Output:
[2025-10-30T01:56:49.371+0000] {subprocess.py:93} INFO - [0m01:56:49  Running with dbt=1.9.0-b2
[2025-10-30T01:56:51.884+0000] {subprocess.py:93} INFO - [0m01:56:51  Registered adapter: postgres=1.8.2
[2025-10-30T01:56:52.266+0000] {subprocess.py:93} INFO - [0m01:56:52  Unable to do partial parsing because saved manifest not found. Starting full parse.
[2025-10-30T01:57:01.014+0000] {subprocess.py:93} INFO - [0m01:57:01  [[33mWARNING[0m]: Did not find matching node for patch with name 'dim_date' in the 'models' section of file 'models/datamart/schema.yml'
[2025-10-30T01:57:01.855+0000] {subprocess.py:93} INFO - [0m01:57:01  Encountered an error:
[2025-10-30T01:57:01.859+0000] {subprocess.py:93} INFO - Compilation Error in test relationships_fact_transactions_ref_dim_card_holder___payment_card_id__passenger_id (models/datamart/schema.yml)
[2025-10-30T01:57:01.863+0000] {subprocess.py:93} INFO -   macro 'dbt_macro__test_relationships' takes no keyword argument 'arguments'
[2025-10-30T01:57:03.664+0000] {subprocess.py:97} INFO - Command exited with return code 2
[2025-10-30T01:57:03.696+0000] {taskinstance.py:2698} ERROR - Task failed with exception
Traceback (most recent call last):
  File "/home/airflow/.local/lib/python3.8/site-packages/airflow/models/taskinstance.py", line 433, in _execute_task
    result = execute_callable(context=context, **execute_callable_kwargs)
  File "/home/airflow/.local/lib/python3.8/site-packages/airflow/operators/bash.py", line 212, in execute
    raise AirflowException(
airflow.exceptions.AirflowException: Bash command failed. The command returned a non-zero exit code 2.
[2025-10-30T01:57:03.705+0000] {taskinstance.py:1138} INFO - Marking task as UP_FOR_RETRY. dag_id=dbt_local_pipeline, task_id=dbt_run, execution_date=20251030T015624, start_date=20251030T015633, end_date=20251030T015703
[2025-10-30T01:57:03.792+0000] {standard_task_runner.py:107} ERROR - Failed to execute job 279 for task dbt_run (Bash command failed. The command returned a non-zero exit code 2.; 537)
[2025-10-30T01:57:03.833+0000] {local_task_job_runner.py:234} INFO - Task exited with return code 1
[2025-10-30T01:57:03.925+0000] {taskinstance.py:3280} INFO - 0 downstream tasks scheduled from follow-on schedule check
