[2025-10-30T02:02:05.272+0000] {taskinstance.py:1956} INFO - Dependencies all met for dep_context=non-requeueable deps ti=<TaskInstance: dbt_local_pipeline.dbt_run manual__2025-10-30T01:56:24.022091+00:00 [queued]>
[2025-10-30T02:02:05.285+0000] {taskinstance.py:1956} INFO - Dependencies all met for dep_context=requeueable deps ti=<TaskInstance: dbt_local_pipeline.dbt_run manual__2025-10-30T01:56:24.022091+00:00 [queued]>
[2025-10-30T02:02:05.286+0000] {taskinstance.py:2170} INFO - Starting attempt 2 of 2
[2025-10-30T02:02:05.307+0000] {taskinstance.py:2191} INFO - Executing <Task(BashOperator): dbt_run> on 2025-10-30 01:56:24.022091+00:00
[2025-10-30T02:02:05.329+0000] {standard_task_runner.py:60} INFO - Started process 608 to run task
[2025-10-30T02:02:05.340+0000] {standard_task_runner.py:87} INFO - Running: ['***', 'tasks', 'run', 'dbt_local_pipeline', 'dbt_run', 'manual__2025-10-30T01:56:24.022091+00:00', '--job-id', '280', '--raw', '--subdir', 'DAGS_FOLDER/dbt_local_dag.py', '--cfg-path', '/tmp/tmpmaiop9ps']
[2025-10-30T02:02:05.350+0000] {standard_task_runner.py:88} INFO - Job 280: Subtask dbt_run
[2025-10-30T02:02:05.477+0000] {task_command.py:423} INFO - Running <TaskInstance: dbt_local_pipeline.dbt_run manual__2025-10-30T01:56:24.022091+00:00 [running]> on host e51a0d90683d
[2025-10-30T02:02:05.595+0000] {taskinstance.py:2480} INFO - Exporting env vars: AIRFLOW_CTX_DAG_OWNER='winardi' AIRFLOW_CTX_DAG_ID='dbt_local_pipeline' AIRFLOW_CTX_TASK_ID='dbt_run' AIRFLOW_CTX_EXECUTION_DATE='2025-10-30T01:56:24.022091+00:00' AIRFLOW_CTX_TRY_NUMBER='2' AIRFLOW_CTX_DAG_RUN_ID='manual__2025-10-30T01:56:24.022091+00:00'
[2025-10-30T02:02:05.597+0000] {subprocess.py:63} INFO - Tmp dir root location: /tmp
[2025-10-30T02:02:05.599+0000] {subprocess.py:75} INFO - Running command: ['/usr/bin/bash', '-c', '\n            cd /opt/***/include/dbt/dbt_project &&             dbt run --profiles-dir /home/***/.dbt --target dev\n        ']
[2025-10-30T02:02:05.617+0000] {subprocess.py:86} INFO - Output:
[2025-10-30T02:02:08.431+0000] {subprocess.py:93} INFO - [0m02:02:08  Running with dbt=1.9.0-b2
[2025-10-30T02:02:08.941+0000] {subprocess.py:93} INFO - [0m02:02:08  Registered adapter: postgres=1.8.2
[2025-10-30T02:02:09.009+0000] {subprocess.py:93} INFO - [0m02:02:09  Unable to do partial parsing because saved manifest not found. Starting full parse.
[2025-10-30T02:02:12.008+0000] {subprocess.py:93} INFO - [0m02:02:12  [[33mWARNING[0m]: Did not find matching node for patch with name 'dim_date' in the 'models' section of file 'models/datamart/schema.yml'
[2025-10-30T02:02:12.340+0000] {subprocess.py:93} INFO - [0m02:02:12  Encountered an error:
[2025-10-30T02:02:12.341+0000] {subprocess.py:93} INFO - Compilation Error in test relationships_fact_transactions_ref_dim_card_holder___payment_card_id__passenger_id (models/datamart/schema.yml)
[2025-10-30T02:02:12.342+0000] {subprocess.py:93} INFO -   macro 'dbt_macro__test_relationships' takes no keyword argument 'arguments'
[2025-10-30T02:02:13.632+0000] {subprocess.py:97} INFO - Command exited with return code 2
[2025-10-30T02:02:13.650+0000] {taskinstance.py:2698} ERROR - Task failed with exception
Traceback (most recent call last):
  File "/home/airflow/.local/lib/python3.8/site-packages/airflow/models/taskinstance.py", line 433, in _execute_task
    result = execute_callable(context=context, **execute_callable_kwargs)
  File "/home/airflow/.local/lib/python3.8/site-packages/airflow/operators/bash.py", line 212, in execute
    raise AirflowException(
airflow.exceptions.AirflowException: Bash command failed. The command returned a non-zero exit code 2.
[2025-10-30T02:02:13.655+0000] {taskinstance.py:1138} INFO - Marking task as FAILED. dag_id=dbt_local_pipeline, task_id=dbt_run, execution_date=20251030T015624, start_date=20251030T020205, end_date=20251030T020213
[2025-10-30T02:02:13.679+0000] {standard_task_runner.py:107} ERROR - Failed to execute job 280 for task dbt_run (Bash command failed. The command returned a non-zero exit code 2.; 608)
[2025-10-30T02:02:13.720+0000] {local_task_job_runner.py:234} INFO - Task exited with return code 1
[2025-10-30T02:02:13.748+0000] {taskinstance.py:3280} INFO - 0 downstream tasks scheduled from follow-on schedule check
