[2025-10-30T14:12:03.676+0000] {taskinstance.py:1956} INFO - Dependencies all met for dep_context=non-requeueable deps ti=<TaskInstance: dag_dbt_pipeline.dbt_run manual__2025-10-30T14:04:59.876062+00:00 [queued]>
[2025-10-30T14:12:03.859+0000] {taskinstance.py:1956} INFO - Dependencies all met for dep_context=requeueable deps ti=<TaskInstance: dag_dbt_pipeline.dbt_run manual__2025-10-30T14:04:59.876062+00:00 [queued]>
[2025-10-30T14:12:03.862+0000] {taskinstance.py:2170} INFO - Starting attempt 2 of 2
[2025-10-30T14:12:04.332+0000] {taskinstance.py:2191} INFO - Executing <Task(BashOperator): dbt_run> on 2025-10-30 14:04:59.876062+00:00
[2025-10-30T14:12:04.364+0000] {standard_task_runner.py:60} INFO - Started process 176 to run task
[2025-10-30T14:12:04.525+0000] {standard_task_runner.py:87} INFO - Running: ['***', 'tasks', 'run', 'dag_dbt_pipeline', 'dbt_run', 'manual__2025-10-30T14:04:59.876062+00:00', '--job-id', '321', '--raw', '--subdir', 'DAGS_FOLDER/dbt_local_dag.py', '--cfg-path', '/tmp/tmpm4m76ous']
[2025-10-30T14:12:04.733+0000] {standard_task_runner.py:88} INFO - Job 321: Subtask dbt_run
[2025-10-30T14:12:05.244+0000] {task_command.py:423} INFO - Running <TaskInstance: dag_dbt_pipeline.dbt_run manual__2025-10-30T14:04:59.876062+00:00 [running]> on host 257bb6028ed5
[2025-10-30T14:12:06.109+0000] {taskinstance.py:2480} INFO - Exporting env vars: AIRFLOW_CTX_DAG_OWNER='winardi' AIRFLOW_CTX_DAG_ID='dag_dbt_pipeline' AIRFLOW_CTX_TASK_ID='dbt_run' AIRFLOW_CTX_EXECUTION_DATE='2025-10-30T14:04:59.876062+00:00' AIRFLOW_CTX_TRY_NUMBER='2' AIRFLOW_CTX_DAG_RUN_ID='manual__2025-10-30T14:04:59.876062+00:00'
[2025-10-30T14:12:06.145+0000] {subprocess.py:63} INFO - Tmp dir root location: /tmp
[2025-10-30T14:12:06.157+0000] {subprocess.py:75} INFO - Running command: ['/usr/bin/bash', '-c', '\n            cd /opt/***/include/dbt/dbt_project &&             dbt run --profiles-dir /home/***/.dbt --target dev\n        ']
[2025-10-30T14:12:06.424+0000] {subprocess.py:86} INFO - Output:
[2025-10-30T14:14:02.351+0000] {subprocess.py:93} INFO - [0m14:14:02  Running with dbt=1.9.0-b2
[2025-10-30T14:14:11.245+0000] {subprocess.py:93} INFO - [0m14:14:11  Registered adapter: postgres=1.8.2
[2025-10-30T14:14:20.795+0000] {subprocess.py:93} INFO - [0m14:14:20  Found 5 models, 14 data tests, 1 source, 423 macros
[2025-10-30T14:14:20.888+0000] {subprocess.py:93} INFO - [0m14:14:20
[2025-10-30T14:14:20.891+0000] {subprocess.py:93} INFO - [0m14:14:20  Concurrency: 1 threads (target='dev')
[2025-10-30T14:14:20.895+0000] {subprocess.py:93} INFO - [0m14:14:20
[2025-10-30T14:14:25.428+0000] {subprocess.py:93} INFO - [0m14:14:25  1 of 5 START sql table model datamart.dim_card_holder .......................... [RUN]
[2025-10-30T14:14:36.608+0000] {subprocess.py:93} INFO - [0m14:14:36  1 of 5 OK created sql table model datamart.dim_card_holder ..................... [[32mSELECT 10000[0m in 11.08s]
[2025-10-30T14:14:36.689+0000] {subprocess.py:93} INFO - [0m14:14:36  2 of 5 START sql table model datamart.dim_corridor ............................. [RUN]
[2025-10-30T14:14:41.175+0000] {subprocess.py:93} INFO - [0m14:14:41  2 of 5 OK created sql table model datamart.dim_corridor ........................ [[32mSELECT 221[0m in 4.47s]
[2025-10-30T14:14:41.216+0000] {subprocess.py:93} INFO - [0m14:14:41  3 of 5 START sql table model datamart.dim_stop ................................. [RUN]
[2025-10-30T14:14:46.149+0000] {subprocess.py:93} INFO - [0m14:14:46  3 of 5 OK created sql table model datamart.dim_stop ............................ [[32mSELECT 5851[0m in 4.90s]
[2025-10-30T14:14:46.203+0000] {subprocess.py:93} INFO - [0m14:14:46  4 of 5 START sql table model datamart.dim_time ................................. [RUN]
[2025-10-30T14:14:50.276+0000] {subprocess.py:93} INFO - [0m14:14:50  4 of 5 OK created sql table model datamart.dim_time ............................ [[32mSELECT 27836[0m in 4.05s]
[2025-10-30T14:14:50.288+0000] {subprocess.py:93} INFO - [0m14:14:50  5 of 5 START sql incremental model datamart.fact_transactions .................. [RUN]
[2025-10-30T14:14:51.322+0000] {subprocess.py:93} INFO - [0m14:14:51  5 of 5 ERROR creating sql incremental model datamart.fact_transactions ......... [[31mERROR[0m in 1.03s]
[2025-10-30T14:14:51.384+0000] {subprocess.py:93} INFO - [0m14:14:51
[2025-10-30T14:14:51.404+0000] {subprocess.py:93} INFO - [0m14:14:51  Finished running 1 incremental model, 4 table models in 0 hours 0 minutes and 30.48 seconds (30.48s).
[2025-10-30T14:14:51.773+0000] {subprocess.py:93} INFO - [0m14:14:51
[2025-10-30T14:14:51.778+0000] {subprocess.py:93} INFO - [0m14:14:51  [31mCompleted with 1 error, 0 partial successs, and 0 warnings:[0m
[2025-10-30T14:14:51.812+0000] {subprocess.py:93} INFO - [0m14:14:51
[2025-10-30T14:14:51.813+0000] {subprocess.py:93} INFO - [0m14:14:51    Database Error in model fact_transactions (models/datamart/fact_transactions.sql)
[2025-10-30T14:14:51.814+0000] {subprocess.py:93} INFO -   relation "source_data" does not exist
[2025-10-30T14:14:51.815+0000] {subprocess.py:93} INFO -   LINE 94: FROM source_data s
[2025-10-30T14:14:51.817+0000] {subprocess.py:93} INFO -                 ^
[2025-10-30T14:14:51.818+0000] {subprocess.py:93} INFO - [0m14:14:51
[2025-10-30T14:14:51.819+0000] {subprocess.py:93} INFO - [0m14:14:51  Done. PASS=4 WARN=0 ERROR=1 SKIP=0 TOTAL=5
[2025-10-30T14:14:55.814+0000] {subprocess.py:97} INFO - Command exited with return code 1
[2025-10-30T14:14:56.023+0000] {taskinstance.py:2698} ERROR - Task failed with exception
Traceback (most recent call last):
  File "/home/airflow/.local/lib/python3.8/site-packages/airflow/models/taskinstance.py", line 433, in _execute_task
    result = execute_callable(context=context, **execute_callable_kwargs)
  File "/home/airflow/.local/lib/python3.8/site-packages/airflow/operators/bash.py", line 212, in execute
    raise AirflowException(
airflow.exceptions.AirflowException: Bash command failed. The command returned a non-zero exit code 1.
[2025-10-30T14:14:56.052+0000] {taskinstance.py:1138} INFO - Marking task as FAILED. dag_id=dag_dbt_pipeline, task_id=dbt_run, execution_date=20251030T140459, start_date=20251030T141203, end_date=20251030T141456
[2025-10-30T14:14:56.163+0000] {standard_task_runner.py:107} ERROR - Failed to execute job 321 for task dbt_run (Bash command failed. The command returned a non-zero exit code 1.; 176)
[2025-10-30T14:14:56.283+0000] {local_task_job_runner.py:234} INFO - Task exited with return code 1
[2025-10-30T14:14:56.408+0000] {taskinstance.py:3280} INFO - 0 downstream tasks scheduled from follow-on schedule check
