[2025-10-29T23:16:21.022+0000] {taskinstance.py:1956} INFO - Dependencies all met for dep_context=non-requeueable deps ti=<TaskInstance: dbt_local_pipeline.dbt_run manual__2025-10-29T23:16:11.927914+00:00 [queued]>
[2025-10-29T23:16:21.045+0000] {taskinstance.py:1956} INFO - Dependencies all met for dep_context=requeueable deps ti=<TaskInstance: dbt_local_pipeline.dbt_run manual__2025-10-29T23:16:11.927914+00:00 [queued]>
[2025-10-29T23:16:21.046+0000] {taskinstance.py:2170} INFO - Starting attempt 1 of 2
[2025-10-29T23:16:21.267+0000] {taskinstance.py:2191} INFO - Executing <Task(BashOperator): dbt_run> on 2025-10-29 23:16:11.927914+00:00
[2025-10-29T23:16:21.285+0000] {standard_task_runner.py:60} INFO - Started process 104 to run task
[2025-10-29T23:16:21.296+0000] {standard_task_runner.py:87} INFO - Running: ['***', 'tasks', 'run', 'dbt_local_pipeline', 'dbt_run', 'manual__2025-10-29T23:16:11.927914+00:00', '--job-id', '268', '--raw', '--subdir', 'DAGS_FOLDER/dbt_local_dag.py', '--cfg-path', '/tmp/tmpp0zq820x']
[2025-10-29T23:16:21.299+0000] {standard_task_runner.py:88} INFO - Job 268: Subtask dbt_run
[2025-10-29T23:16:21.586+0000] {task_command.py:423} INFO - Running <TaskInstance: dbt_local_pipeline.dbt_run manual__2025-10-29T23:16:11.927914+00:00 [running]> on host e51a0d90683d
[2025-10-29T23:16:22.049+0000] {taskinstance.py:2480} INFO - Exporting env vars: AIRFLOW_CTX_DAG_OWNER='winardi' AIRFLOW_CTX_DAG_ID='dbt_local_pipeline' AIRFLOW_CTX_TASK_ID='dbt_run' AIRFLOW_CTX_EXECUTION_DATE='2025-10-29T23:16:11.927914+00:00' AIRFLOW_CTX_TRY_NUMBER='1' AIRFLOW_CTX_DAG_RUN_ID='manual__2025-10-29T23:16:11.927914+00:00'
[2025-10-29T23:16:22.053+0000] {subprocess.py:63} INFO - Tmp dir root location: /tmp
[2025-10-29T23:16:22.057+0000] {subprocess.py:75} INFO - Running command: ['/usr/bin/bash', '-c', '\n        cd /Users/User/Documents/Data_engineer/my_project/***_project/include/dbt/dbt_project &&         source /Users/User/Documents/Data_engineer/my_project/***_project/venv/bin/activate &&         dbt run --profiles-dir /Users/User/.dbt --target dev\n    ']
[2025-10-29T23:16:22.090+0000] {subprocess.py:86} INFO - Output:
[2025-10-29T23:16:22.140+0000] {subprocess.py:93} INFO - /usr/bin/bash: line 2: cd: /Users/User/Documents/Data_engineer/my_project/***_project/include/dbt/dbt_project: No such file or directory
[2025-10-29T23:16:22.142+0000] {subprocess.py:97} INFO - Command exited with return code 1
[2025-10-29T23:16:22.187+0000] {taskinstance.py:2698} ERROR - Task failed with exception
Traceback (most recent call last):
  File "/home/airflow/.local/lib/python3.8/site-packages/airflow/models/taskinstance.py", line 433, in _execute_task
    result = execute_callable(context=context, **execute_callable_kwargs)
  File "/home/airflow/.local/lib/python3.8/site-packages/airflow/operators/bash.py", line 212, in execute
    raise AirflowException(
airflow.exceptions.AirflowException: Bash command failed. The command returned a non-zero exit code 1.
[2025-10-29T23:16:22.198+0000] {taskinstance.py:1138} INFO - Marking task as UP_FOR_RETRY. dag_id=dbt_local_pipeline, task_id=dbt_run, execution_date=20251029T231611, start_date=20251029T231621, end_date=20251029T231622
[2025-10-29T23:16:22.307+0000] {standard_task_runner.py:107} ERROR - Failed to execute job 268 for task dbt_run (Bash command failed. The command returned a non-zero exit code 1.; 104)
[2025-10-29T23:16:22.354+0000] {local_task_job_runner.py:234} INFO - Task exited with return code 1
[2025-10-29T23:16:22.457+0000] {taskinstance.py:3280} INFO - 0 downstream tasks scheduled from follow-on schedule check
