[2025-10-24T02:50:05.846+0000] {taskinstance.py:1956} INFO - Dependencies all met for dep_context=non-requeueable deps ti=<TaskInstance: spark_validate_staging_dag.validate_and_load_staging manual__2025-10-24T02:40:18.782108+00:00 [queued]>
[2025-10-24T02:50:05.875+0000] {taskinstance.py:1956} INFO - Dependencies all met for dep_context=requeueable deps ti=<TaskInstance: spark_validate_staging_dag.validate_and_load_staging manual__2025-10-24T02:40:18.782108+00:00 [queued]>
[2025-10-24T02:50:05.876+0000] {taskinstance.py:2170} INFO - Starting attempt 2 of 2
[2025-10-24T02:50:05.901+0000] {taskinstance.py:2191} INFO - Executing <Task(PythonOperator): validate_and_load_staging> on 2025-10-24 02:40:18.782108+00:00
[2025-10-24T02:50:05.909+0000] {standard_task_runner.py:60} INFO - Started process 1040 to run task
[2025-10-24T02:50:05.954+0000] {standard_task_runner.py:87} INFO - Running: ['***', 'tasks', 'run', 'spark_validate_staging_dag', 'validate_and_load_staging', 'manual__2025-10-24T02:40:18.782108+00:00', '--job-id', '182', '--raw', '--subdir', 'DAGS_FOLDER/etl_validate_staging_dag.py', '--cfg-path', '/tmp/tmp6x1cjtfm']
[2025-10-24T02:50:05.959+0000] {standard_task_runner.py:88} INFO - Job 182: Subtask validate_and_load_staging
[2025-10-24T02:50:06.158+0000] {task_command.py:423} INFO - Running <TaskInstance: spark_validate_staging_dag.validate_and_load_staging manual__2025-10-24T02:40:18.782108+00:00 [running]> on host 2ef039423968
[2025-10-24T02:50:06.390+0000] {taskinstance.py:2480} INFO - Exporting env vars: AIRFLOW_CTX_DAG_OWNER='winardi' AIRFLOW_CTX_DAG_ID='spark_validate_staging_dag' AIRFLOW_CTX_TASK_ID='validate_and_load_staging' AIRFLOW_CTX_EXECUTION_DATE='2025-10-24T02:40:18.782108+00:00' AIRFLOW_CTX_TRY_NUMBER='2' AIRFLOW_CTX_DAG_RUN_ID='manual__2025-10-24T02:40:18.782108+00:00'
[2025-10-24T02:50:06.463+0000] {base.py:83} INFO - Using connection ID 'pg_conn' for task execution.
[2025-10-24T02:51:45.509+0000] {etl_validate_staging_dag.py:47} INFO - Data loaded. Total rows: 189500
[2025-10-24T02:52:04.409+0000] {etl_validate_staging_dag.py:84} INFO - Null value check result:
[2025-10-24T02:52:04.411+0000] {etl_validate_staging_dag.py:86} INFO - transID: 189500 null values
[2025-10-24T02:52:04.414+0000] {etl_validate_staging_dag.py:86} INFO - payCardID: 0 null values
[2025-10-24T02:52:04.415+0000] {etl_validate_staging_dag.py:86} INFO - corridorID: 177001 null values
[2025-10-24T02:52:04.416+0000] {etl_validate_staging_dag.py:86} INFO - direction: 0 null values
[2025-10-24T02:52:04.417+0000] {etl_validate_staging_dag.py:86} INFO - tapInStops: 7241 null values
[2025-10-24T02:52:04.418+0000] {etl_validate_staging_dag.py:86} INFO - tapInTime: 0 null values
[2025-10-24T02:52:04.419+0000] {etl_validate_staging_dag.py:86} INFO - tapOutStops: 12369 null values
[2025-10-24T02:52:04.420+0000] {etl_validate_staging_dag.py:86} INFO - tapOutTime: 6720 null values
[2025-10-24T02:52:04.421+0000] {etl_validate_staging_dag.py:86} INFO - payAmount: 3718 null values
[2025-10-24T02:52:04.422+0000] {etl_validate_staging_dag.py:86} INFO - tapInStopsLat: 0 null values
[2025-10-24T02:52:04.423+0000] {etl_validate_staging_dag.py:86} INFO - tapInStopsLon: 0 null values
[2025-10-24T02:52:04.424+0000] {etl_validate_staging_dag.py:86} INFO - tapOutStopsLat: 6720 null values
[2025-10-24T02:52:04.426+0000] {etl_validate_staging_dag.py:86} INFO - tapOutStopsLon: 6720 null values
[2025-10-24T02:52:04.431+0000] {taskinstance.py:2698} ERROR - Task failed with exception
Traceback (most recent call last):
  File "/home/airflow/.local/lib/python3.8/site-packages/airflow/models/taskinstance.py", line 433, in _execute_task
    result = execute_callable(context=context, **execute_callable_kwargs)
  File "/home/airflow/.local/lib/python3.8/site-packages/airflow/operators/python.py", line 199, in execute
    return_value = self.execute_callable()
  File "/home/airflow/.local/lib/python3.8/site-packages/airflow/operators/python.py", line 216, in execute_callable
    return self.python_callable(*self.op_args, **self.op_kwargs)
  File "/opt/airflow/dags/etl_validate_staging_dag.py", line 91, in validate_and_load_staging
    raise ValueError(f"Data validation failed! Nulls found in columns: {invalid_cols}")
ValueError: Data validation failed! Nulls found in columns: ['transID', 'corridorID', 'tapInStops', 'tapOutStops', 'tapOutTime', 'payAmount', 'tapOutStopsLat', 'tapOutStopsLon']
[2025-10-24T02:52:04.519+0000] {taskinstance.py:1138} INFO - Marking task as FAILED. dag_id=spark_validate_staging_dag, task_id=validate_and_load_staging, execution_date=20251024T024018, start_date=20251024T025005, end_date=20251024T025204
[2025-10-24T02:52:04.626+0000] {standard_task_runner.py:107} ERROR - Failed to execute job 182 for task validate_and_load_staging (Data validation failed! Nulls found in columns: ['transID', 'corridorID', 'tapInStops', 'tapOutStops', 'tapOutTime', 'payAmount', 'tapOutStopsLat', 'tapOutStopsLon']; 1040)
[2025-10-24T02:52:04.829+0000] {local_task_job_runner.py:234} INFO - Task exited with return code 1
[2025-10-24T02:52:05.114+0000] {taskinstance.py:3280} INFO - 0 downstream tasks scheduled from follow-on schedule check
