[2025-10-29T12:36:28.839+0000] {taskinstance.py:1956} INFO - Dependencies all met for dep_context=non-requeueable deps ti=<TaskInstance: scheduled_dbt_pg_daily.dbt_run manual__2025-10-29T12:36:17.605698+00:00 [queued]>
[2025-10-29T12:36:28.874+0000] {taskinstance.py:1956} INFO - Dependencies all met for dep_context=requeueable deps ti=<TaskInstance: scheduled_dbt_pg_daily.dbt_run manual__2025-10-29T12:36:17.605698+00:00 [queued]>
[2025-10-29T12:36:28.878+0000] {taskinstance.py:2170} INFO - Starting attempt 1 of 2
[2025-10-29T12:36:28.969+0000] {taskinstance.py:2191} INFO - Executing <Task(BashOperator): dbt_run> on 2025-10-29 12:36:17.605698+00:00
[2025-10-29T12:36:29.008+0000] {standard_task_runner.py:60} INFO - Started process 498 to run task
[2025-10-29T12:36:29.023+0000] {standard_task_runner.py:87} INFO - Running: ['***', 'tasks', 'run', 'scheduled_dbt_pg_daily', 'dbt_run', 'manual__2025-10-29T12:36:17.605698+00:00', '--job-id', '250', '--raw', '--subdir', 'DAGS_FOLDER/pg_dbt.py', '--cfg-path', '/tmp/tmpt_tcpaus']
[2025-10-29T12:36:29.037+0000] {standard_task_runner.py:88} INFO - Job 250: Subtask dbt_run
[2025-10-29T12:36:29.339+0000] {task_command.py:423} INFO - Running <TaskInstance: scheduled_dbt_pg_daily.dbt_run manual__2025-10-29T12:36:17.605698+00:00 [running]> on host 891764070a1e
[2025-10-29T12:36:29.755+0000] {taskinstance.py:2480} INFO - Exporting env vars: AIRFLOW_CTX_DAG_OWNER='***' AIRFLOW_CTX_DAG_ID='scheduled_dbt_pg_daily' AIRFLOW_CTX_TASK_ID='dbt_run' AIRFLOW_CTX_EXECUTION_DATE='2025-10-29T12:36:17.605698+00:00' AIRFLOW_CTX_TRY_NUMBER='1' AIRFLOW_CTX_DAG_RUN_ID='manual__2025-10-29T12:36:17.605698+00:00'
[2025-10-29T12:36:29.786+0000] {subprocess.py:63} INFO - Tmp dir root location: /tmp
[2025-10-29T12:36:29.799+0000] {subprocess.py:75} INFO - Running command: ['/usr/bin/bash', '-c', 'cd /usr/local/***/include/dbt/dbt_project; source /usr/local/***/venv/bin/activate; dbt run --profiles-dir /usr/local/***/include/dbt/dbt_project/dbt-profiles/']
[2025-10-29T12:36:29.852+0000] {subprocess.py:86} INFO - Output:
[2025-10-29T12:36:29.916+0000] {subprocess.py:93} INFO - /usr/bin/bash: line 1: cd: /usr/local/***/include/dbt/dbt_project: No such file or directory
[2025-10-29T12:36:29.918+0000] {subprocess.py:93} INFO - /usr/bin/bash: line 1: /usr/local/***/venv/bin/activate: No such file or directory
[2025-10-29T12:36:30.016+0000] {subprocess.py:93} INFO - /usr/bin/bash: line 1: dbt: command not found
[2025-10-29T12:36:30.027+0000] {subprocess.py:97} INFO - Command exited with return code 127
[2025-10-29T12:36:30.065+0000] {taskinstance.py:2698} ERROR - Task failed with exception
Traceback (most recent call last):
  File "/home/airflow/.local/lib/python3.8/site-packages/airflow/models/taskinstance.py", line 433, in _execute_task
    result = execute_callable(context=context, **execute_callable_kwargs)
  File "/home/airflow/.local/lib/python3.8/site-packages/airflow/operators/bash.py", line 212, in execute
    raise AirflowException(
airflow.exceptions.AirflowException: Bash command failed. The command returned a non-zero exit code 127.
[2025-10-29T12:36:30.089+0000] {taskinstance.py:1138} INFO - Marking task as UP_FOR_RETRY. dag_id=scheduled_dbt_pg_daily, task_id=dbt_run, execution_date=20251029T123617, start_date=20251029T123628, end_date=20251029T123630
[2025-10-29T12:36:30.571+0000] {standard_task_runner.py:107} ERROR - Failed to execute job 250 for task dbt_run (Bash command failed. The command returned a non-zero exit code 127.; 498)
[2025-10-29T12:36:31.361+0000] {local_task_job_runner.py:234} INFO - Task exited with return code 1
[2025-10-29T12:36:31.419+0000] {taskinstance.py:3280} INFO - 0 downstream tasks scheduled from follow-on schedule check
