[2025-10-29T12:41:35.338+0000] {taskinstance.py:1956} INFO - Dependencies all met for dep_context=non-requeueable deps ti=<TaskInstance: scheduled_dbt_pg_daily.dbt_run manual__2025-10-29T12:36:17.605698+00:00 [queued]>
[2025-10-29T12:41:35.565+0000] {taskinstance.py:1956} INFO - Dependencies all met for dep_context=requeueable deps ti=<TaskInstance: scheduled_dbt_pg_daily.dbt_run manual__2025-10-29T12:36:17.605698+00:00 [queued]>
[2025-10-29T12:41:35.599+0000] {taskinstance.py:2170} INFO - Starting attempt 2 of 2
[2025-10-29T12:41:35.821+0000] {taskinstance.py:2191} INFO - Executing <Task(BashOperator): dbt_run> on 2025-10-29 12:36:17.605698+00:00
[2025-10-29T12:41:35.874+0000] {standard_task_runner.py:60} INFO - Started process 566 to run task
[2025-10-29T12:41:35.895+0000] {standard_task_runner.py:87} INFO - Running: ['***', 'tasks', 'run', 'scheduled_dbt_pg_daily', 'dbt_run', 'manual__2025-10-29T12:36:17.605698+00:00', '--job-id', '251', '--raw', '--subdir', 'DAGS_FOLDER/pg_dbt.py', '--cfg-path', '/tmp/tmpj18oosu7']
[2025-10-29T12:41:35.957+0000] {standard_task_runner.py:88} INFO - Job 251: Subtask dbt_run
[2025-10-29T12:41:36.406+0000] {task_command.py:423} INFO - Running <TaskInstance: scheduled_dbt_pg_daily.dbt_run manual__2025-10-29T12:36:17.605698+00:00 [running]> on host 891764070a1e
[2025-10-29T12:41:37.131+0000] {taskinstance.py:2480} INFO - Exporting env vars: AIRFLOW_CTX_DAG_OWNER='***' AIRFLOW_CTX_DAG_ID='scheduled_dbt_pg_daily' AIRFLOW_CTX_TASK_ID='dbt_run' AIRFLOW_CTX_EXECUTION_DATE='2025-10-29T12:36:17.605698+00:00' AIRFLOW_CTX_TRY_NUMBER='2' AIRFLOW_CTX_DAG_RUN_ID='manual__2025-10-29T12:36:17.605698+00:00'
[2025-10-29T12:41:37.139+0000] {subprocess.py:63} INFO - Tmp dir root location: /tmp
[2025-10-29T12:41:37.147+0000] {subprocess.py:75} INFO - Running command: ['/usr/bin/bash', '-c', 'cd /usr/local/***/include/dbt/dbt_project; source /usr/local/***/venv/bin/activate; dbt run --profiles-dir /usr/local/***/include/dbt/dbt_project/dbt-profiles/']
[2025-10-29T12:41:37.283+0000] {subprocess.py:86} INFO - Output:
[2025-10-29T12:41:37.370+0000] {subprocess.py:93} INFO - /usr/bin/bash: line 1: cd: /usr/local/***/include/dbt/dbt_project: No such file or directory
[2025-10-29T12:41:37.457+0000] {subprocess.py:93} INFO - /usr/bin/bash: line 1: /usr/local/***/venv/bin/activate: No such file or directory
[2025-10-29T12:41:37.517+0000] {subprocess.py:93} INFO - /usr/bin/bash: line 1: dbt: command not found
[2025-10-29T12:41:37.565+0000] {subprocess.py:97} INFO - Command exited with return code 127
[2025-10-29T12:41:37.858+0000] {taskinstance.py:2698} ERROR - Task failed with exception
Traceback (most recent call last):
  File "/home/airflow/.local/lib/python3.8/site-packages/airflow/models/taskinstance.py", line 433, in _execute_task
    result = execute_callable(context=context, **execute_callable_kwargs)
  File "/home/airflow/.local/lib/python3.8/site-packages/airflow/operators/bash.py", line 212, in execute
    raise AirflowException(
airflow.exceptions.AirflowException: Bash command failed. The command returned a non-zero exit code 127.
[2025-10-29T12:41:37.872+0000] {taskinstance.py:1138} INFO - Marking task as FAILED. dag_id=scheduled_dbt_pg_daily, task_id=dbt_run, execution_date=20251029T123617, start_date=20251029T124135, end_date=20251029T124137
[2025-10-29T12:41:37.956+0000] {standard_task_runner.py:107} ERROR - Failed to execute job 251 for task dbt_run (Bash command failed. The command returned a non-zero exit code 127.; 566)
[2025-10-29T12:41:38.048+0000] {local_task_job_runner.py:234} INFO - Task exited with return code 1
[2025-10-29T12:41:38.374+0000] {taskinstance.py:3280} INFO - 0 downstream tasks scheduled from follow-on schedule check
