[2025-10-29T23:34:52.491+0000] {taskinstance.py:1956} INFO - Dependencies all met for dep_context=non-requeueable deps ti=<TaskInstance: dbt_local_pipeline.dbt_run manual__2025-10-29T23:29:14.150459+00:00 [queued]>
[2025-10-29T23:34:52.517+0000] {taskinstance.py:1956} INFO - Dependencies all met for dep_context=requeueable deps ti=<TaskInstance: dbt_local_pipeline.dbt_run manual__2025-10-29T23:29:14.150459+00:00 [queued]>
[2025-10-29T23:34:52.517+0000] {taskinstance.py:2170} INFO - Starting attempt 2 of 2
[2025-10-29T23:34:52.540+0000] {taskinstance.py:2191} INFO - Executing <Task(BashOperator): dbt_run> on 2025-10-29 23:29:14.150459+00:00
[2025-10-29T23:34:52.547+0000] {standard_task_runner.py:60} INFO - Started process 331 to run task
[2025-10-29T23:34:52.553+0000] {standard_task_runner.py:87} INFO - Running: ['***', 'tasks', 'run', 'dbt_local_pipeline', 'dbt_run', 'manual__2025-10-29T23:29:14.150459+00:00', '--job-id', '271', '--raw', '--subdir', 'DAGS_FOLDER/dbt_local_dag.py', '--cfg-path', '/tmp/tmpzipxdhsn']
[2025-10-29T23:34:52.555+0000] {standard_task_runner.py:88} INFO - Job 271: Subtask dbt_run
[2025-10-29T23:34:52.765+0000] {task_command.py:423} INFO - Running <TaskInstance: dbt_local_pipeline.dbt_run manual__2025-10-29T23:29:14.150459+00:00 [running]> on host e51a0d90683d
[2025-10-29T23:34:52.957+0000] {taskinstance.py:2480} INFO - Exporting env vars: AIRFLOW_CTX_DAG_OWNER='winardi' AIRFLOW_CTX_DAG_ID='dbt_local_pipeline' AIRFLOW_CTX_TASK_ID='dbt_run' AIRFLOW_CTX_EXECUTION_DATE='2025-10-29T23:29:14.150459+00:00' AIRFLOW_CTX_TRY_NUMBER='2' AIRFLOW_CTX_DAG_RUN_ID='manual__2025-10-29T23:29:14.150459+00:00'
[2025-10-29T23:34:52.961+0000] {subprocess.py:63} INFO - Tmp dir root location: /tmp
[2025-10-29T23:34:52.963+0000] {subprocess.py:75} INFO - Running command: ['/usr/bin/bash', '-c', '\n            cd /opt/***/include/dbt/dbt_project &&             dbt run --profiles-dir /home/***/.dbt --target dev\n        ']
[2025-10-29T23:34:52.989+0000] {subprocess.py:86} INFO - Output:
[2025-10-29T23:34:53.037+0000] {subprocess.py:93} INFO - /usr/bin/bash: line 2: dbt: command not found
[2025-10-29T23:34:53.040+0000] {subprocess.py:97} INFO - Command exited with return code 127
[2025-10-29T23:34:53.059+0000] {taskinstance.py:2698} ERROR - Task failed with exception
Traceback (most recent call last):
  File "/home/airflow/.local/lib/python3.8/site-packages/airflow/models/taskinstance.py", line 433, in _execute_task
    result = execute_callable(context=context, **execute_callable_kwargs)
  File "/home/airflow/.local/lib/python3.8/site-packages/airflow/operators/bash.py", line 212, in execute
    raise AirflowException(
airflow.exceptions.AirflowException: Bash command failed. The command returned a non-zero exit code 127.
[2025-10-29T23:34:53.064+0000] {taskinstance.py:1138} INFO - Marking task as FAILED. dag_id=dbt_local_pipeline, task_id=dbt_run, execution_date=20251029T232914, start_date=20251029T233452, end_date=20251029T233453
[2025-10-29T23:34:53.169+0000] {standard_task_runner.py:107} ERROR - Failed to execute job 271 for task dbt_run (Bash command failed. The command returned a non-zero exit code 127.; 331)
[2025-10-29T23:34:53.255+0000] {local_task_job_runner.py:234} INFO - Task exited with return code 1
[2025-10-29T23:34:53.381+0000] {taskinstance.py:3280} INFO - 0 downstream tasks scheduled from follow-on schedule check
