[2025-10-30T01:26:35.433+0000] {taskinstance.py:1956} INFO - Dependencies all met for dep_context=non-requeueable deps ti=<TaskInstance: dbt_local_pipeline.dbt_run scheduled__2025-10-29T00:00:00+00:00 [queued]>
[2025-10-30T01:26:35.501+0000] {taskinstance.py:1956} INFO - Dependencies all met for dep_context=requeueable deps ti=<TaskInstance: dbt_local_pipeline.dbt_run scheduled__2025-10-29T00:00:00+00:00 [queued]>
[2025-10-30T01:26:35.504+0000] {taskinstance.py:2170} INFO - Starting attempt 2 of 2
[2025-10-30T01:26:35.757+0000] {taskinstance.py:2191} INFO - Executing <Task(BashOperator): dbt_run> on 2025-10-29 00:00:00+00:00
[2025-10-30T01:26:35.798+0000] {standard_task_runner.py:60} INFO - Started process 152 to run task
[2025-10-30T01:26:35.805+0000] {standard_task_runner.py:87} INFO - Running: ['***', 'tasks', 'run', 'dbt_local_pipeline', 'dbt_run', 'scheduled__2025-10-29T00:00:00+00:00', '--job-id', '278', '--raw', '--subdir', 'DAGS_FOLDER/dbt_local_dag.py', '--cfg-path', '/tmp/tmps07xbzu3']
[2025-10-30T01:26:35.815+0000] {standard_task_runner.py:88} INFO - Job 278: Subtask dbt_run
[2025-10-30T01:26:36.387+0000] {task_command.py:423} INFO - Running <TaskInstance: dbt_local_pipeline.dbt_run scheduled__2025-10-29T00:00:00+00:00 [running]> on host e51a0d90683d
[2025-10-30T01:26:36.618+0000] {taskinstance.py:2480} INFO - Exporting env vars: AIRFLOW_CTX_DAG_OWNER='winardi' AIRFLOW_CTX_DAG_ID='dbt_local_pipeline' AIRFLOW_CTX_TASK_ID='dbt_run' AIRFLOW_CTX_EXECUTION_DATE='2025-10-29T00:00:00+00:00' AIRFLOW_CTX_TRY_NUMBER='2' AIRFLOW_CTX_DAG_RUN_ID='scheduled__2025-10-29T00:00:00+00:00'
[2025-10-30T01:26:36.622+0000] {subprocess.py:63} INFO - Tmp dir root location: /tmp
[2025-10-30T01:26:36.625+0000] {subprocess.py:75} INFO - Running command: ['/usr/bin/bash', '-c', '\n            cd /opt/***/include/dbt/dbt_project &&             dbt run --profiles-dir /home/***/.dbt --target dev\n        ']
[2025-10-30T01:26:36.700+0000] {subprocess.py:86} INFO - Output:
[2025-10-30T01:26:45.292+0000] {subprocess.py:93} INFO - [0m01:26:45  Running with dbt=1.9.0-b2
[2025-10-30T01:26:46.354+0000] {subprocess.py:93} INFO - [0m01:26:46  Registered adapter: postgres=1.8.2
[2025-10-30T01:26:48.735+0000] {subprocess.py:93} INFO - [0m01:26:48  Unable to do partial parsing because of a version mismatch
[2025-10-30T01:26:58.242+0000] {subprocess.py:93} INFO - [0m01:26:58  [[33mWARNING[0m]: Did not find matching node for patch with name 'dim_date' in the 'models' section of file 'models/datamart/schema.yml'
[2025-10-30T01:26:59.208+0000] {subprocess.py:93} INFO - [0m01:26:59  Encountered an error:
[2025-10-30T01:26:59.218+0000] {subprocess.py:93} INFO - Compilation Error in test relationships_fact_transactions_ref_dim_card_holder___payment_card_id__passenger_id (models/datamart/schema.yml)
[2025-10-30T01:26:59.227+0000] {subprocess.py:93} INFO -   macro 'dbt_macro__test_relationships' takes no keyword argument 'arguments'
[2025-10-30T01:27:02.030+0000] {subprocess.py:97} INFO - Command exited with return code 2
[2025-10-30T01:27:02.068+0000] {taskinstance.py:2698} ERROR - Task failed with exception
Traceback (most recent call last):
  File "/home/airflow/.local/lib/python3.8/site-packages/airflow/models/taskinstance.py", line 433, in _execute_task
    result = execute_callable(context=context, **execute_callable_kwargs)
  File "/home/airflow/.local/lib/python3.8/site-packages/airflow/operators/bash.py", line 212, in execute
    raise AirflowException(
airflow.exceptions.AirflowException: Bash command failed. The command returned a non-zero exit code 2.
[2025-10-30T01:27:02.074+0000] {taskinstance.py:1138} INFO - Marking task as FAILED. dag_id=dbt_local_pipeline, task_id=dbt_run, execution_date=20251029T000000, start_date=20251030T012635, end_date=20251030T012702
[2025-10-30T01:27:02.113+0000] {standard_task_runner.py:107} ERROR - Failed to execute job 278 for task dbt_run (Bash command failed. The command returned a non-zero exit code 2.; 152)
[2025-10-30T01:27:02.153+0000] {local_task_job_runner.py:234} INFO - Task exited with return code 1
[2025-10-30T01:27:02.244+0000] {taskinstance.py:3280} INFO - 0 downstream tasks scheduled from follow-on schedule check
