[2025-10-29T23:48:22.269+0000] {taskinstance.py:1956} INFO - Dependencies all met for dep_context=non-requeueable deps ti=<TaskInstance: dbt_local_pipeline.dbt_run manual__2025-10-29T23:48:16.959500+00:00 [queued]>
[2025-10-29T23:48:22.289+0000] {taskinstance.py:1956} INFO - Dependencies all met for dep_context=requeueable deps ti=<TaskInstance: dbt_local_pipeline.dbt_run manual__2025-10-29T23:48:16.959500+00:00 [queued]>
[2025-10-29T23:48:22.290+0000] {taskinstance.py:2170} INFO - Starting attempt 1 of 2
[2025-10-29T23:48:22.431+0000] {taskinstance.py:2191} INFO - Executing <Task(BashOperator): dbt_run> on 2025-10-29 23:48:16.959500+00:00
[2025-10-29T23:48:22.545+0000] {standard_task_runner.py:60} INFO - Started process 488 to run task
[2025-10-29T23:48:22.568+0000] {standard_task_runner.py:87} INFO - Running: ['***', 'tasks', 'run', 'dbt_local_pipeline', 'dbt_run', 'manual__2025-10-29T23:48:16.959500+00:00', '--job-id', '272', '--raw', '--subdir', 'DAGS_FOLDER/dbt_local_dag.py', '--cfg-path', '/tmp/tmpk19u_o_8']
[2025-10-29T23:48:22.578+0000] {standard_task_runner.py:88} INFO - Job 272: Subtask dbt_run
[2025-10-29T23:48:22.765+0000] {task_command.py:423} INFO - Running <TaskInstance: dbt_local_pipeline.dbt_run manual__2025-10-29T23:48:16.959500+00:00 [running]> on host e51a0d90683d
[2025-10-29T23:48:23.041+0000] {taskinstance.py:2480} INFO - Exporting env vars: AIRFLOW_CTX_DAG_OWNER='winardi' AIRFLOW_CTX_DAG_ID='dbt_local_pipeline' AIRFLOW_CTX_TASK_ID='dbt_run' AIRFLOW_CTX_EXECUTION_DATE='2025-10-29T23:48:16.959500+00:00' AIRFLOW_CTX_TRY_NUMBER='1' AIRFLOW_CTX_DAG_RUN_ID='manual__2025-10-29T23:48:16.959500+00:00'
[2025-10-29T23:48:23.045+0000] {subprocess.py:63} INFO - Tmp dir root location: /tmp
[2025-10-29T23:48:23.155+0000] {subprocess.py:75} INFO - Running command: ['/usr/bin/bash', '-c', '\n            cd /opt/***/include/dbt/dbt_project &&             dbt run --profiles-dir /home/***/.dbt --target dev\n        ']
[2025-10-29T23:48:23.223+0000] {subprocess.py:86} INFO - Output:
[2025-10-29T23:48:23.254+0000] {subprocess.py:93} INFO - /usr/bin/bash: line 2: dbt: command not found
[2025-10-29T23:48:23.256+0000] {subprocess.py:97} INFO - Command exited with return code 127
[2025-10-29T23:48:23.284+0000] {taskinstance.py:2698} ERROR - Task failed with exception
Traceback (most recent call last):
  File "/home/airflow/.local/lib/python3.8/site-packages/airflow/models/taskinstance.py", line 433, in _execute_task
    result = execute_callable(context=context, **execute_callable_kwargs)
  File "/home/airflow/.local/lib/python3.8/site-packages/airflow/operators/bash.py", line 212, in execute
    raise AirflowException(
airflow.exceptions.AirflowException: Bash command failed. The command returned a non-zero exit code 127.
[2025-10-29T23:48:23.296+0000] {taskinstance.py:1138} INFO - Marking task as UP_FOR_RETRY. dag_id=dbt_local_pipeline, task_id=dbt_run, execution_date=20251029T234816, start_date=20251029T234822, end_date=20251029T234823
[2025-10-29T23:48:23.616+0000] {standard_task_runner.py:107} ERROR - Failed to execute job 272 for task dbt_run (Bash command failed. The command returned a non-zero exit code 127.; 488)
[2025-10-29T23:48:23.663+0000] {local_task_job_runner.py:234} INFO - Task exited with return code 1
[2025-10-29T23:48:23.712+0000] {taskinstance.py:3280} INFO - 0 downstream tasks scheduled from follow-on schedule check
