[2025-10-30T14:16:21.112+0000] {taskinstance.py:1956} INFO - Dependencies all met for dep_context=non-requeueable deps ti=<TaskInstance: dag_dbt_pipeline.dbt_run manual__2025-10-30T14:16:13.943140+00:00 [queued]>
[2025-10-30T14:16:21.135+0000] {taskinstance.py:1956} INFO - Dependencies all met for dep_context=requeueable deps ti=<TaskInstance: dag_dbt_pipeline.dbt_run manual__2025-10-30T14:16:13.943140+00:00 [queued]>
[2025-10-30T14:16:21.136+0000] {taskinstance.py:2170} INFO - Starting attempt 1 of 2
[2025-10-30T14:16:21.184+0000] {taskinstance.py:2191} INFO - Executing <Task(BashOperator): dbt_run> on 2025-10-30 14:16:13.943140+00:00
[2025-10-30T14:16:21.193+0000] {standard_task_runner.py:60} INFO - Started process 245 to run task
[2025-10-30T14:16:21.201+0000] {standard_task_runner.py:87} INFO - Running: ['***', 'tasks', 'run', 'dag_dbt_pipeline', 'dbt_run', 'manual__2025-10-30T14:16:13.943140+00:00', '--job-id', '322', '--raw', '--subdir', 'DAGS_FOLDER/dbt_local_dag.py', '--cfg-path', '/tmp/tmp6ad6fnym']
[2025-10-30T14:16:21.204+0000] {standard_task_runner.py:88} INFO - Job 322: Subtask dbt_run
[2025-10-30T14:16:21.543+0000] {task_command.py:423} INFO - Running <TaskInstance: dag_dbt_pipeline.dbt_run manual__2025-10-30T14:16:13.943140+00:00 [running]> on host 257bb6028ed5
[2025-10-30T14:16:22.264+0000] {taskinstance.py:2480} INFO - Exporting env vars: AIRFLOW_CTX_DAG_OWNER='winardi' AIRFLOW_CTX_DAG_ID='dag_dbt_pipeline' AIRFLOW_CTX_TASK_ID='dbt_run' AIRFLOW_CTX_EXECUTION_DATE='2025-10-30T14:16:13.943140+00:00' AIRFLOW_CTX_TRY_NUMBER='1' AIRFLOW_CTX_DAG_RUN_ID='manual__2025-10-30T14:16:13.943140+00:00'
[2025-10-30T14:16:22.280+0000] {subprocess.py:63} INFO - Tmp dir root location: /tmp
[2025-10-30T14:16:22.292+0000] {subprocess.py:75} INFO - Running command: ['/usr/bin/bash', '-c', '\n            cd /opt/***/include/dbt/dbt_project &&             dbt run --profiles-dir /home/***/.dbt --target dev\n        ']
[2025-10-30T14:16:22.366+0000] {subprocess.py:86} INFO - Output:
[2025-10-30T14:16:31.968+0000] {subprocess.py:93} INFO - [0m14:16:31  Running with dbt=1.9.0-b2
[2025-10-30T14:16:32.632+0000] {subprocess.py:93} INFO - [0m14:16:32  Registered adapter: postgres=1.8.2
[2025-10-30T14:16:35.806+0000] {subprocess.py:93} INFO - [0m14:16:35  Found 5 models, 14 data tests, 1 source, 423 macros
[2025-10-30T14:16:35.815+0000] {subprocess.py:93} INFO - [0m14:16:35
[2025-10-30T14:16:35.817+0000] {subprocess.py:93} INFO - [0m14:16:35  Concurrency: 1 threads (target='dev')
[2025-10-30T14:16:35.819+0000] {subprocess.py:93} INFO - [0m14:16:35
[2025-10-30T14:16:36.122+0000] {subprocess.py:93} INFO - [0m14:16:36  1 of 5 START sql table model datamart.dim_card_holder .......................... [RUN]
[2025-10-30T14:16:37.493+0000] {subprocess.py:93} INFO - [0m14:16:37  1 of 5 OK created sql table model datamart.dim_card_holder ..................... [[32mSELECT 10000[0m in 1.36s]
[2025-10-30T14:16:37.505+0000] {subprocess.py:93} INFO - [0m14:16:37  2 of 5 START sql table model datamart.dim_corridor ............................. [RUN]
[2025-10-30T14:16:39.003+0000] {subprocess.py:93} INFO - [0m14:16:39  2 of 5 OK created sql table model datamart.dim_corridor ........................ [[32mSELECT 221[0m in 1.49s]
[2025-10-30T14:16:39.032+0000] {subprocess.py:93} INFO - [0m14:16:39  3 of 5 START sql table model datamart.dim_stop ................................. [RUN]
[2025-10-30T14:16:40.368+0000] {subprocess.py:93} INFO - [0m14:16:40  3 of 5 OK created sql table model datamart.dim_stop ............................ [[32mSELECT 5851[0m in 1.33s]
[2025-10-30T14:16:40.378+0000] {subprocess.py:93} INFO - [0m14:16:40  4 of 5 START sql table model datamart.dim_time ................................. [RUN]
[2025-10-30T14:16:42.891+0000] {subprocess.py:93} INFO - [0m14:16:42  4 of 5 OK created sql table model datamart.dim_time ............................ [[32mSELECT 27836[0m in 2.51s]
[2025-10-30T14:16:42.901+0000] {subprocess.py:93} INFO - [0m14:16:42  5 of 5 START sql incremental model datamart.fact_transactions .................. [RUN]
[2025-10-30T14:21:30.138+0000] {job.py:213} ERROR - Job heartbeat got an exception
Traceback (most recent call last):
  File "/home/airflow/.local/lib/python3.8/site-packages/sqlalchemy/engine/base.py", line 1094, in _commit_impl
  File "/home/airflow/.local/lib/python3.8/site-packages/sqlalchemy/engine/default.py", line 686, in do_commit
psycopg2.OperationalError: server closed the connection unexpectedly
	This probably means the server terminated abnormally
	before or while processing the request.


The above exception was the direct cause of the following exception:

Traceback (most recent call last):
  File "/home/airflow/.local/lib/python3.8/site-packages/airflow/jobs/job.py", line 202, in heartbeat
  File "/home/airflow/.local/lib/python3.8/site-packages/airflow/api_internal/internal_api_call.py", line 114, in wrapper
  File "/home/airflow/.local/lib/python3.8/site-packages/airflow/utils/session.py", line 76, in wrapper
  File "/home/airflow/.local/lib/python3.8/site-packages/airflow/jobs/job.py", line 351, in _update_heartbeat
  File "/home/airflow/.local/lib/python3.8/site-packages/sqlalchemy/orm/session.py", line 1454, in commit
  File "/home/airflow/.local/lib/python3.8/site-packages/sqlalchemy/orm/session.py", line 839, in commit
  File "/home/airflow/.local/lib/python3.8/site-packages/sqlalchemy/engine/base.py", line 2469, in commit
  File "/home/airflow/.local/lib/python3.8/site-packages/sqlalchemy/engine/base.py", line 2659, in _do_commit
  File "/home/airflow/.local/lib/python3.8/site-packages/sqlalchemy/engine/base.py", line 2630, in _connection_commit_impl
  File "/home/airflow/.local/lib/python3.8/site-packages/sqlalchemy/engine/base.py", line 1096, in _commit_impl
  File "/home/airflow/.local/lib/python3.8/site-packages/sqlalchemy/engine/base.py", line 2134, in _handle_dbapi_exception
  File "/home/airflow/.local/lib/python3.8/site-packages/sqlalchemy/util/compat.py", line 211, in raise_
  File "/home/airflow/.local/lib/python3.8/site-packages/sqlalchemy/engine/base.py", line 1094, in _commit_impl
  File "/home/airflow/.local/lib/python3.8/site-packages/sqlalchemy/engine/default.py", line 686, in do_commit
sqlalchemy.exc.OperationalError: (psycopg2.OperationalError) server closed the connection unexpectedly
	This probably means the server terminated abnormally
	before or while processing the request.

(Background on this error at: https://sqlalche.me/e/14/e3q8)
[2025-10-30T14:21:30.736+0000] {job.py:221} ERROR - Job heartbeat failed with error. Scheduler is in unhealthy state
[2025-10-30T14:21:31.319+0000] {process_utils.py:131} INFO - Sending 15 to group 245. PIDs of all processes in the group: [246, 247, 249, 245]
[2025-10-30T14:21:31.428+0000] {process_utils.py:86} INFO - Sending the signal 15 to group 245
[2025-10-30T14:21:31.621+0000] {taskinstance.py:2450} ERROR - Received SIGTERM. Terminating subprocesses.
[2025-10-30T14:21:32.607+0000] {subprocess.py:104} INFO - Sending SIGTERM signal to process group
[2025-10-30T14:21:33.805+0000] {process_utils.py:79} INFO - Process psutil.Process(pid=247, status='terminated', started='14:16:22') (247) terminated with exit code None
[2025-10-30T14:21:36.004+0000] {taskinstance.py:2698} ERROR - Task failed with exception
Traceback (most recent call last):
  File "/home/airflow/.local/lib/python3.8/site-packages/airflow/hooks/subprocess.py", line 91, in run_command
  File "/home/airflow/.local/lib/python3.8/site-packages/airflow/models/taskinstance.py", line 2452, in signal_handler
    raise AirflowException("Task received SIGTERM signal")
airflow.exceptions.AirflowException: Task received SIGTERM signal

During handling of the above exception, another exception occurred:

Traceback (most recent call last):
  File "/home/airflow/.local/lib/python3.8/site-packages/airflow/models/taskinstance.py", line 433, in _execute_task
    result = execute_callable(context=context, **execute_callable_kwargs)
  File "/home/airflow/.local/lib/python3.8/site-packages/airflow/operators/bash.py", line 203, in execute
  File "/home/airflow/.local/lib/python3.8/site-packages/airflow/hooks/subprocess.py", line 98, in run_command
  File "/usr/local/lib/python3.8/contextlib.py", line 525, in __exit__
  File "/usr/local/lib/python3.8/contextlib.py", line 510, in __exit__
  File "/usr/local/lib/python3.8/tempfile.py", line 827, in __exit__
  File "/usr/local/lib/python3.8/tempfile.py", line 831, in cleanup
  File "/usr/local/lib/python3.8/tempfile.py", line 813, in _rmtree
  File "/usr/local/lib/python3.8/shutil.py", line 722, in rmtree
  File "/usr/local/lib/python3.8/shutil.py", line 720, in rmtree
OSError: [Errno 5] Input/output error: '/tmp/airflowtmp2odvpb5e'
[2025-10-30T14:21:36.904+0000] {process_utils.py:79} INFO - Process psutil.Process(pid=249, status='terminated', started='14:16:32') (249) terminated with exit code None
[2025-10-30T14:21:54.593+0000] {standard_task_runner.py:107} ERROR - Failed to execute job 322 for task dbt_run ((psycopg2.OperationalError) connection to server at "postgres" (172.18.0.3), port 5432 failed: server closed the connection unexpectedly
	This probably means the server terminated abnormally
	before or while processing the request.

(Background on this error at: https://sqlalche.me/e/14/e3q8); 245)
[2025-10-30T14:21:55.606+0000] {process_utils.py:79} INFO - Process psutil.Process(pid=246, status='terminated', started='14:16:22') (246) terminated with exit code None
[2025-10-30T14:21:56.761+0000] {process_utils.py:79} INFO - Process psutil.Process(pid=245, status='terminated', exitcode=1, started='14:16:21') (245) terminated with exit code 1
