[2025-10-30T14:47:46.540+0000] {scheduler_job_runner.py:1586} WARNING - Marking task instance <TaskInstance: dag_dbt_pipeline.dbt_run manual__2025-10-30T14:16:13.943140+00:00 [queued]> stuck in queued as failed. If the task instance has available retries, it will be retried.
[2025-10-30T14:47:47.241+0000] {scheduler_job_runner.py:781} ERROR - Executor reports task instance <TaskInstance: dag_dbt_pipeline.dbt_run manual__2025-10-30T14:16:13.943140+00:00 [queued]> finished (failed) although the task says it's queued. (Info: None) Was the task killed externally?
